def test_retry_on_exceptions_with_backoff() -> None:
    """Make sure retry function has accurate number of attempts."""
    global call_count
    assert fn_with_exception(None)

    call_count = 0
    with pytest.raises(ValueError):
        fn_with_exception(ValueError)
    assert call_count == 1

    call_count = 0
    with pytest.raises(ValueError):
        retry_on_exceptions_with_backoff(
            lambda: fn_with_exception(ValueError),
            [ErrorToRetry(ValueError)],
            max_tries=3,
            min_backoff_secs=0.0,
        )
    assert call_count == 3

    # different exception will not get retried
    call_count = 0
    with pytest.raises(TypeError):
        retry_on_exceptions_with_backoff(
            lambda: fn_with_exception(TypeError),
            [ErrorToRetry(ValueError)],
            max_tries=3,
        )
    assert call_count == 1
